[I 2024-12-05 13:26:56.454 ServerApp] jupyter_lsp | extension was successfully linked.
[I 2024-12-05 13:26:56.459 ServerApp] jupyter_server_terminals | extension was successfully linked.
[I 2024-12-05 13:26:56.466 ServerApp] jupyterlab | extension was successfully linked.
[I 2024-12-05 13:26:56.472 ServerApp] notebook | extension was successfully linked.
[I 2024-12-05 13:26:56.693 ServerApp] notebook_shim | extension was successfully linked.
[I 2024-12-05 13:26:56.710 ServerApp] notebook_shim | extension was successfully loaded.
[I 2024-12-05 13:26:56.712 ServerApp] jupyter_lsp | extension was successfully loaded.
[I 2024-12-05 13:26:56.713 ServerApp] jupyter_server_terminals | extension was successfully loaded.
[I 2024-12-05 13:26:56.715 LabApp] JupyterLab extension loaded from /home/leroquan@eawag.wroot.emp-eaw.ch/miniconda3/envs/eddytools/lib/python3.10/site-packages/jupyterlab
[I 2024-12-05 13:26:56.715 LabApp] JupyterLab application directory is /home/leroquan@eawag.wroot.emp-eaw.ch/miniconda3/envs/eddytools/share/jupyter/lab
[I 2024-12-05 13:26:56.715 LabApp] Extension Manager is 'pypi'.
[W 2024-12-05 13:26:56.715 LabApp] Failed to instantiate the extension manager pypi. Falling back to read-only manager.
    Traceback (most recent call last):
      File "/home/leroquan@eawag.wroot.emp-eaw.ch/miniconda3/envs/eddytools/lib/python3.10/site-packages/jupyterlab/labapp.py", line 837, in initialize_handlers
        ext_manager = manager_factory(app_options, listings_config, self)
      File "/home/leroquan@eawag.wroot.emp-eaw.ch/miniconda3/envs/eddytools/lib/python3.10/site-packages/jupyterlab/extensions/__init__.py", line 46, in get_pypi_manager
        return PyPIExtensionManager(app_options, ext_options, parent)
      File "/home/leroquan@eawag.wroot.emp-eaw.ch/miniconda3/envs/eddytools/lib/python3.10/site-packages/jupyterlab/extensions/pypi.py", line 134, in __init__
        self._httpx_client = httpx.AsyncClient(proxies=proxies)
    TypeError: AsyncClient.__init__() got an unexpected keyword argument 'proxies'
[I 2024-12-05 13:26:56.720 ServerApp] jupyterlab | extension was successfully loaded.
[I 2024-12-05 13:26:56.725 ServerApp] notebook | extension was successfully loaded.
[I 2024-12-05 13:26:56.726 ServerApp] Serving notebooks from local directory: /home/leroquan@eawag.wroot.emp-eaw.ch/eddytools
[I 2024-12-05 13:26:56.726 ServerApp] Jupyter Server 2.14.2 is running at:
[I 2024-12-05 13:26:56.726 ServerApp] http://KBALL-LAKEN-L.eawag.wroot.emp-eaw.ch:8888/tree?token=32ba5253ec03bb3281527702d9c95d302797508106987ce1
[I 2024-12-05 13:26:56.726 ServerApp]     http://127.0.0.1:8888/tree?token=32ba5253ec03bb3281527702d9c95d302797508106987ce1
[I 2024-12-05 13:26:56.726 ServerApp] Use Control-C to stop this server and shut down all kernels (twice to skip confirmation).
[C 2024-12-05 13:26:56.729 ServerApp] 
    
    To access the server, open this file in a browser:
        file:///home/leroquan%40eawag.wroot.emp-eaw.ch/.local/share/jupyter/runtime/jpserver-684296-open.html
    Or copy and paste one of these URLs:
        http://KBALL-LAKEN-L.eawag.wroot.emp-eaw.ch:8888/tree?token=32ba5253ec03bb3281527702d9c95d302797508106987ce1
        http://127.0.0.1:8888/tree?token=32ba5253ec03bb3281527702d9c95d302797508106987ce1
[I 2024-12-05 13:26:56.748 ServerApp] Skipped non-installed server(s): bash-language-server, dockerfile-language-server-nodejs, javascript-typescript-langserver, jedi-language-server, julia-language-server, pyright, python-language-server, python-lsp-server, r-languageserver, sql-language-server, texlab, typescript-language-server, unified-language-server, vscode-css-languageserver-bin, vscode-html-languageserver-bin, vscode-json-languageserver-bin, yaml-language-server
[I 2024-12-05 13:31:38.186 ServerApp] Kernel started: 9051d8ee-e1af-419d-b1e7-913dcf25132d
[I 2024-12-05 13:31:38.819 ServerApp] Connecting to kernel 9051d8ee-e1af-419d-b1e7-913dcf25132d.
[I 2024-12-05 13:36:31.672 ServerApp] Copying examples/run_eddytools_example_MITgcm_OW.ipynb to /workspace
[W 2024-12-05 13:36:31.755 ServerApp] Notebook examples/run_eddytools_example_MITgcm_OW.ipynb is not trusted
[W 2024-12-05 13:36:31.782 ServerApp] Notebook examples/run_eddytools_example_MITgcm_OW.ipynb is not trusted
[W 2024-12-05 13:36:31.784 ServerApp] Notebook workspace/run_eddytools_example_MITgcm_OW.ipynb is not trusted
[I 2024-12-05 13:36:57.436 ServerApp] Creating new directory in /workspace
[W 2024-12-05 13:37:19.439 ServerApp] Notebook workspace/OW/run_eddytools_MITgcm_OW.ipynb is not trusted
[W 2024-12-05 13:37:22.622 ServerApp] Notebook workspace/OW/run_eddytools_MITgcm_OW.ipynb is not trusted
[I 2024-12-05 13:37:24.503 ServerApp] Kernel started: e52636e5-1627-4d0f-a76c-b48203ab130e
[I 2024-12-05 13:37:25.856 ServerApp] Connecting to kernel e52636e5-1627-4d0f-a76c-b48203ab130e.
[I 2024-12-05 13:37:39.588 ServerApp] Saving file at /run_eddytools_nencioli.ipynb
[I 2024-12-05 13:39:23.677 ServerApp] Saving file at /workspace/OW/run_eddytools_MITgcm_OW.ipynb
[W 2024-12-05 13:39:23.681 ServerApp] Notebook workspace/OW/run_eddytools_MITgcm_OW.ipynb is not trusted
[I 2024-12-05 13:39:42.128 ServerApp] Saving file at /run_eddytools_nencioli.ipynb
[I 2024-12-05 13:41:28.822 ServerApp] Saving file at /workspace/OW/run_eddytools_MITgcm_OW.ipynb
[W 2024-12-05 13:41:28.827 ServerApp] Notebook workspace/OW/run_eddytools_MITgcm_OW.ipynb is not trusted
[I 2024-12-05 13:43:32.264 ServerApp] Saving file at /workspace/OW/run_eddytools_MITgcm_OW.ipynb
[W 2024-12-05 13:43:32.281 ServerApp] Notebook workspace/OW/run_eddytools_MITgcm_OW.ipynb is not trusted
[I 2024-12-05 13:45:39.158 ServerApp] Saving file at /workspace/OW/run_eddytools_MITgcm_OW.ipynb
[W 2024-12-05 13:45:39.166 ServerApp] Notebook workspace/OW/run_eddytools_MITgcm_OW.ipynb is not trusted
[I 2024-12-05 13:47:50.863 ServerApp] Saving file at /workspace/OW/run_eddytools_MITgcm_OW.ipynb
[W 2024-12-05 13:47:51.006 ServerApp] Notebook workspace/OW/run_eddytools_MITgcm_OW.ipynb is not trusted
[I 2024-12-05 13:51:07.199 ServerApp] Saving file at /workspace/OW/run_eddytools_MITgcm_OW.ipynb
[W 2024-12-05 13:51:07.202 ServerApp] Notebook workspace/OW/run_eddytools_MITgcm_OW.ipynb is not trusted
[I 2024-12-05 13:53:12.559 ServerApp] Saving file at /workspace/OW/run_eddytools_MITgcm_OW.ipynb
[W 2024-12-05 13:53:12.562 ServerApp] Notebook workspace/OW/run_eddytools_MITgcm_OW.ipynb is not trusted
[I 2024-12-05 15:03:18.730 ServerApp] Saving file at /workspace/OW/run_eddytools_MITgcm_OW.ipynb
[W 2024-12-05 15:03:18.732 ServerApp] Notebook workspace/OW/run_eddytools_MITgcm_OW.ipynb is not trusted
[I 2024-12-05 15:05:23.238 ServerApp] Saving file at /workspace/OW/run_eddytools_MITgcm_OW.ipynb
[W 2024-12-05 15:05:23.241 ServerApp] Notebook workspace/OW/run_eddytools_MITgcm_OW.ipynb is not trusted
[I 2024-12-05 15:07:27.257 ServerApp] Saving file at /workspace/OW/run_eddytools_MITgcm_OW.ipynb
[W 2024-12-05 15:07:27.259 ServerApp] Notebook workspace/OW/run_eddytools_MITgcm_OW.ipynb is not trusted
[I 2024-12-05 15:09:30.958 ServerApp] Saving file at /workspace/OW/run_eddytools_MITgcm_OW.ipynb
[W 2024-12-05 15:09:30.961 ServerApp] Notebook workspace/OW/run_eddytools_MITgcm_OW.ipynb is not trusted
[I 2024-12-05 15:11:34.133 ServerApp] Saving file at /workspace/OW/run_eddytools_MITgcm_OW.ipynb
[W 2024-12-05 15:11:34.136 ServerApp] Notebook workspace/OW/run_eddytools_MITgcm_OW.ipynb is not trusted
[I 2024-12-05 15:13:40.987 ServerApp] Saving file at /workspace/OW/run_eddytools_MITgcm_OW.ipynb
[W 2024-12-05 15:13:40.989 ServerApp] Notebook workspace/OW/run_eddytools_MITgcm_OW.ipynb is not trusted
[W 2024-12-05 15:15:09.620 ServerApp] 400 GET /api/contents/workspace/test_2021-07-28_eddies_OW0.3_test.pickle?type=file&content=1&format=text&1733408109626 (152.88.189.137): /home/leroquan@eawag.wroot.emp-eaw.ch/eddytools/workspace/test_2021-07-28_eddies_OW0.3_test.pickle is not UTF-8 encoded
[W 2024-12-05 15:15:09.620 ServerApp] wrote error: '/home/leroquan@eawag.wroot.emp-eaw.ch/eddytools/workspace/test_2021-07-28_eddies_OW0.3_test.pickle is not UTF-8 encoded'
    Traceback (most recent call last):
      File "/home/leroquan@eawag.wroot.emp-eaw.ch/miniconda3/envs/eddytools/lib/python3.10/site-packages/jupyter_server/services/contents/fileio.py", line 536, in _read_file
        (bcontent.decode("utf8"), "text", bcontent)
    UnicodeDecodeError: 'utf-8' codec can't decode byte 0x80 in position 0: invalid start byte
    
    The above exception was the direct cause of the following exception:
    
    Traceback (most recent call last):
      File "/home/leroquan@eawag.wroot.emp-eaw.ch/miniconda3/envs/eddytools/lib/python3.10/site-packages/tornado/web.py", line 1713, in _execute
        result = await result
      File "/home/leroquan@eawag.wroot.emp-eaw.ch/miniconda3/envs/eddytools/lib/python3.10/site-packages/jupyter_server/auth/decorator.py", line 73, in inner
        return await out
      File "/home/leroquan@eawag.wroot.emp-eaw.ch/miniconda3/envs/eddytools/lib/python3.10/site-packages/jupyter_server/services/contents/handlers.py", line 154, in get
        model = await ensure_async(
      File "/home/leroquan@eawag.wroot.emp-eaw.ch/miniconda3/envs/eddytools/lib/python3.10/site-packages/jupyter_core/utils/__init__.py", line 184, in ensure_async
        result = await obj
      File "/home/leroquan@eawag.wroot.emp-eaw.ch/miniconda3/envs/eddytools/lib/python3.10/site-packages/jupyter_server/services/contents/filemanager.py", line 926, in get
        model = await self._file_model(
      File "/home/leroquan@eawag.wroot.emp-eaw.ch/miniconda3/envs/eddytools/lib/python3.10/site-packages/jupyter_server/services/contents/filemanager.py", line 835, in _file_model
        content, format, bytes_content = await self._read_file(os_path, format, raw=True)  # type: ignore[misc]
      File "/home/leroquan@eawag.wroot.emp-eaw.ch/miniconda3/envs/eddytools/lib/python3.10/site-packages/jupyter_server/services/contents/fileio.py", line 545, in _read_file
        raise HTTPError(
    tornado.web.HTTPError: HTTP 400: bad format (/home/leroquan@eawag.wroot.emp-eaw.ch/eddytools/workspace/test_2021-07-28_eddies_OW0.3_test.pickle is not UTF-8 encoded)
[W 2024-12-05 15:15:09.626 ServerApp] 400 GET /api/contents/workspace/test_2021-07-28_eddies_OW0.3_test.pickle?type=file&content=1&format=text&1733408109626 (ac7e55a81aed495c919adc20a5de7af4@152.88.189.137) 8.49ms referer=http://kball-laken-l.eawag.wroot.emp-eaw.ch:8888/tree/workspace
[W 2024-12-05 15:15:11.807 ServerApp] 400 GET /api/contents/workspace/test_2021-07-28_eddies_OW0.3_test.pickle?type=file&content=1&format=text&1733408111826 (152.88.189.137): /home/leroquan@eawag.wroot.emp-eaw.ch/eddytools/workspace/test_2021-07-28_eddies_OW0.3_test.pickle is not UTF-8 encoded
[W 2024-12-05 15:15:11.807 ServerApp] wrote error: '/home/leroquan@eawag.wroot.emp-eaw.ch/eddytools/workspace/test_2021-07-28_eddies_OW0.3_test.pickle is not UTF-8 encoded'
    Traceback (most recent call last):
      File "/home/leroquan@eawag.wroot.emp-eaw.ch/miniconda3/envs/eddytools/lib/python3.10/site-packages/jupyter_server/services/contents/fileio.py", line 536, in _read_file
        (bcontent.decode("utf8"), "text", bcontent)
    UnicodeDecodeError: 'utf-8' codec can't decode byte 0x80 in position 0: invalid start byte
    
    The above exception was the direct cause of the following exception:
    
    Traceback (most recent call last):
      File "/home/leroquan@eawag.wroot.emp-eaw.ch/miniconda3/envs/eddytools/lib/python3.10/site-packages/tornado/web.py", line 1713, in _execute
        result = await result
      File "/home/leroquan@eawag.wroot.emp-eaw.ch/miniconda3/envs/eddytools/lib/python3.10/site-packages/jupyter_server/auth/decorator.py", line 73, in inner
        return await out
      File "/home/leroquan@eawag.wroot.emp-eaw.ch/miniconda3/envs/eddytools/lib/python3.10/site-packages/jupyter_server/services/contents/handlers.py", line 154, in get
        model = await ensure_async(
      File "/home/leroquan@eawag.wroot.emp-eaw.ch/miniconda3/envs/eddytools/lib/python3.10/site-packages/jupyter_core/utils/__init__.py", line 184, in ensure_async
        result = await obj
      File "/home/leroquan@eawag.wroot.emp-eaw.ch/miniconda3/envs/eddytools/lib/python3.10/site-packages/jupyter_server/services/contents/filemanager.py", line 926, in get
        model = await self._file_model(
      File "/home/leroquan@eawag.wroot.emp-eaw.ch/miniconda3/envs/eddytools/lib/python3.10/site-packages/jupyter_server/services/contents/filemanager.py", line 835, in _file_model
        content, format, bytes_content = await self._read_file(os_path, format, raw=True)  # type: ignore[misc]
      File "/home/leroquan@eawag.wroot.emp-eaw.ch/miniconda3/envs/eddytools/lib/python3.10/site-packages/jupyter_server/services/contents/fileio.py", line 545, in _read_file
        raise HTTPError(
    tornado.web.HTTPError: HTTP 400: bad format (/home/leroquan@eawag.wroot.emp-eaw.ch/eddytools/workspace/test_2021-07-28_eddies_OW0.3_test.pickle is not UTF-8 encoded)
[W 2024-12-05 15:15:11.808 ServerApp] 400 GET /api/contents/workspace/test_2021-07-28_eddies_OW0.3_test.pickle?type=file&content=1&format=text&1733408111826 (ac7e55a81aed495c919adc20a5de7af4@152.88.189.137) 3.89ms referer=http://kball-laken-l.eawag.wroot.emp-eaw.ch:8888/edit/workspace/test_2021-07-28_eddies_OW0.3_test.pickle
[W 2024-12-05 15:15:31.168 ServerApp] 409 PATCH /api/contents/workspace/OW.png?1733408131167 (152.88.189.137): File already exists: workspace/OW/OW.png
[W 2024-12-05 15:15:31.169 ServerApp] wrote error: 'File already exists: workspace/OW/OW.png'
    Traceback (most recent call last):
      File "/home/leroquan@eawag.wroot.emp-eaw.ch/miniconda3/envs/eddytools/lib/python3.10/site-packages/tornado/web.py", line 1713, in _execute
        result = await result
      File "/home/leroquan@eawag.wroot.emp-eaw.ch/miniconda3/envs/eddytools/lib/python3.10/site-packages/jupyter_server/auth/decorator.py", line 73, in inner
        return await out
      File "/home/leroquan@eawag.wroot.emp-eaw.ch/miniconda3/envs/eddytools/lib/python3.10/site-packages/jupyter_server/services/contents/handlers.py", line 204, in patch
        model = await ensure_async(cm.update(model, path))
      File "/home/leroquan@eawag.wroot.emp-eaw.ch/miniconda3/envs/eddytools/lib/python3.10/site-packages/jupyter_core/utils/__init__.py", line 184, in ensure_async
        result = await obj
      File "/home/leroquan@eawag.wroot.emp-eaw.ch/miniconda3/envs/eddytools/lib/python3.10/site-packages/jupyter_server/services/contents/manager.py", line 919, in update
        await self.rename(path, new_path)
      File "/home/leroquan@eawag.wroot.emp-eaw.ch/miniconda3/envs/eddytools/lib/python3.10/site-packages/jupyter_server/services/contents/manager.py", line 906, in rename
        await self.rename_file(old_path, new_path)
      File "/home/leroquan@eawag.wroot.emp-eaw.ch/miniconda3/envs/eddytools/lib/python3.10/site-packages/jupyter_server/services/contents/filemanager.py", line 1064, in rename_file
        raise web.HTTPError(409, "File already exists: %s" % new_path)
    tornado.web.HTTPError: HTTP 409: Conflict (File already exists: workspace/OW/OW.png)
[W 2024-12-05 15:15:31.170 ServerApp] 409 PATCH /api/contents/workspace/OW.png?1733408131167 (ac7e55a81aed495c919adc20a5de7af4@152.88.189.137) 3.97ms referer=http://kball-laken-l.eawag.wroot.emp-eaw.ch:8888/tree/workspace
[W 2024-12-05 15:15:34.582 ServerApp] delete /workspace/OW/OW.png
[I 2024-12-05 15:15:44.801 ServerApp] Saving file at /workspace/OW/run_eddytools_MITgcm_OW.ipynb
[W 2024-12-05 15:15:44.803 ServerApp] Notebook workspace/OW/run_eddytools_MITgcm_OW.ipynb is not trusted
